Workbook
Name Slicer_Entry_Type: #N/A
Name Slicer_popularity_Traffic: #N/A
Name Slicer_Site_Classification: #N/A
Name Slicer_State: #N/A
Name Slicer_Type: #N/A
Name Slicer_Zone: #N/A

Sheet Raw Dataset
B1: Zone | C1: State | D1: City | E1: Name | F1: Type | G1: Establishment Year | H1: time needed to visit in hrs | I1: Google review rating | J1: Entrance Fee in INR | K1: Airport with 50km Radius | L1: Weekly Off | M1: Significance | N1: DSLR Allowed | O1: Number of google review in lakhs | P1: Best Time to visit
A2: 0 | B2: Northern | C2: Delhi | D2: Delhi | E2: India Gate | F2: War Memorial | G2: 1921 | H2: 0.5 | I2: 4.6 | J2: 0 | K2: Yes | L2: None | M2: Historical | N2: Yes | O2: 2.6 | P2: Evening
A3: 1 | B3: Northern | C3: Delhi | D3: Delhi | E3: Humayun's Tomb | F3: Tomb | G3: 1572 | H3: 2 | I3: 4.5 | J3: 30 | K3: Yes | L3: None | M3: Historical | N3: Yes | O3: 0.4 | P3: Afternoon
A4: 2 | B4: Northern | C4: Delhi | D4: Delhi | E4: Akshardham Temple | F4: Temple | G4: 2005 | H4: 5 | I4: 4.6 | J4: 60 | K4: Yes | L4: None | M4: Religious | N4: No | O4: 0.4 | P4: Afternoon
A5: 3 | B5: Northern | C5: Delhi | D5: Delhi | E5: Waste to Wonder Park | F5: Theme Park | G5: 2019 | H5: 2 | I5: 4.1 | J5: 50 | K5: Yes | L5: Monday | M5: Environmental | N5: Yes | O5: 0.27 | P5: Evening
A6: 4 | B6: Northern | C6: Delhi | D6: Delhi | E6: Jantar Mantar | F6: Observatory | G6: 1724 | H6: 2 | I6: 4.2 | J6: 15 | K6: Yes | L6: None | M6: Scientific | N6: Yes | O6: 0.31 | P6: Morning
A7: 5 | B7: Northern | C7: Delhi | D7: Delhi | E7: Chandni Chowk | F7: Market | G7: 1700 | H7: 3 | I7: 4.2 | J7: 0 | K7: Yes | L7: Sunday | M7: Market | N7: Yes | O7: 0.25 | P7: Afternoon
A8: 6 | B8: Northern | C8: Delhi | D8: Delhi | E8: Lotus Temple | F8: Temple | G8: 1986 | H8: 1 | I8: 4.5 | J8: 0 | K8: Yes | L8: Monday | M8: Religious | N8: Yes | O8: 0.59 | P8: Evening
A9: 7 | B9: Northern | C9: Delhi | D9: Delhi | E9: Red Fort | F9: Fort | G9: 1648 | H9: 2 | I9: 4.5 | J9: 35 | K9: Yes | L9: None | M9: Historical | N9: Yes | O9: 1.5 | P9: Afternoon
A10: 8 | B10: Northern | C10: Delhi | D10: Delhi | E10: Agrasen ki Baoli | F10: Stepwell | G10: 1400 | H10: 1 | I10: 4.2 | J10: 0 | K10: Yes | L10: None | M10: Historical | N10: Yes | O10: 0.41 | P10: Afternoon
A11: 9 | B11: Northern | C11: Delhi | D11: Delhi | E11: Sunder Nursery | F11: Park | G11: 1600 | H11: 2 | I11: 4.6 | J11: 0 | K11: Yes | L11: None | M11: Botanical | N11: Yes | O11: 0.16 | P11: Afternoon
A12: 10 | B12: Northern | C12: Delhi | D12: Delhi | E12: Garden of Five Senses | F12: Park | G12: 2003 | H12: 2 | I12: 4.1 | J12: 35 | K12: Yes | L12: None | M12: Botanical | N12: Yes | O12: 0.23 | P12: Morning
A13: 11 | B13: Northern | C13: Delhi | D13: Delhi | E13: Lodhi Garden | F13: Park | G13: 1500 | H13: 1 | I13: 4.5 | J13: 0 | K13: Yes | L13: None | M13: Botanical | N13: Yes | O13: 0.48 | P13: All
... A17: 15 | B17: Northern | C17: Delhi | D17: Delhi | E17: National Science Centre | F17: Science | G17: 1992 | H17: 5 | I17: 4.4 | J17: 70 | K17: Yes | L17: None | M17: Scientific | N17: Yes | O17: 0.23 | P17: All
A18: 16 | B18: Western | C18: Maharastra | D18: Mumbai | E18: Marine Drive | F18: Promenade | G18: Unknown | H18: 2 | I18: 4.5 | J18: 0 | K18: Yes | L18: None | M18: Scenic | N18: Yes | O18: 1.5 | P18: Evening
A19: 17 | B19: Western | C19: Maharastra | D19: Mumbai | E19: Gateway of India | F19: Monument | G19: 1924 | H19: 1 | I19: 4.6 | J19: 0 | K19: Yes | L19: None | M19: Historical | N19: Yes | O19: 3.6 | P19: All
A20: 18 | B20: Western | C20: Maharastra | D20: Mumbai | E20: Chhatrapati Shivaji Maharaj Vastu Sangrahalaya | F20: Museum | G20: 1922 | H20: 1 | I20: 4.6 | J20: 500 | K20: Yes | L20: None | M20: Historical | N20: Yes | O20: 0.34 | P20: All
A21: 19 | B21: Western | C21: Maharastra | D21: Mumbai | E21: Sanjay Gandhi National Park | F21: National Park | G21: 1996 | H21: 3 | I21: 4.3 | J21: 50 | K21: Yes | L21: Monday | M21: Wildlife | N21: Yes | O21: 0.6 | P21: All
A22: 20 | B22: Western | C22: Maharastra | D22: Mumbai | E22: Siddhivinayak Temple | F22: Temple | G22: 1881 | H22: 2 | I22: 4.8 | J22: 0 | K22: Yes | L22: None | M22: Religious | N22: No | O22: 1.05 | P22: All
A23: 21 | B23: Western | C23: Maharastra | D23: Mumbai | E23: Mahalaxmi Temple | F23: Temple | G23: 1831 | H23: 1 | I23: 4.7 | J23: 0 | K23: Yes | L23: None | M23: Religious | N23: No | O23: 0.33 | P23: All
A24: 22 | B24: Western | C24: Maharastra | D24: Mumbai | E24: Haji Ali Dargah | F24: Religious Shrine | G24: 1431 | H24: 2 | I24: 4.4 | J24: 0 | K24: Yes | L24: None | M24: Religious | N24: No | O24: 0.16 | P24: All
A25: 23 | B25: Western | C25: Maharastra | D25: Mumbai | E25: Chowpatty Beach | F25: Beach | G25: Unknown | H25: 2 | I25: 4.3 | J25: 0 | K25: Yes | L25: None | M25: Recreational | N25: Yes | O25: 0.05 | P25: Evening
A26: 24 | B26: Western | C26: Maharastra | D26: Mumbai | E26: Essel World | F26: Amusement Park | G26: 1986 | H26: 5 | I26: 4.3 | J26: 1149 | K26: Yes | L26: None | M26: Recreational | N26: Yes | O26: 0.27 | P26: All
A27: 25 | B27: Western | C27: Maharastra | D27: Mumbai | E27: Elephanta Caves | F27: Monument | G27: 1987 | H27: 4 | I27: 4.3 | J27: 550 | K27: Yes | L27: None | M27: Historical | N27: Yes | O27: 0.35 | P27: All
A28: 26 | B28: Western | C28: Maharastra | D28: Lonavala | E28: Imagicaa | F28: Amusement Park | G28: 2013 | H28: 5 | I28: 1.4 | J28: 1149 | K28: No | L28: Monday | M28: Recreational | N28: Yes | O28: 0.95 | P28: All
A29: 27 | B29: Southern | C29: Karnataka | D29: Bangalore | E29: Bangalore Palace | F29: Palace | G29: 1878 | H29: 2 | I29: 4.2 | J29: 500 | K29: Yes | L29: Monday | M29: Historical | N29: Yes | O29: 0.9 | P29: Morning
A30: 28 | B30: Southern | C30: Karnataka | D30: Bangalore | E30: Lalbagh Botanical Garden | F30: Botanical Garden | G30: 1760 | H30: 1.5 | I30: 4.4 | J30: 20 | K30: Yes | L30: None | M30: Nature | N30: Yes | O30: 1.5 | P30: Evening
A31: 29 | B31: Southern | C31: Karnataka | D31: Bangalore | E31: Cubbon Park | F31: Park | G31: 1870 | H31: 1 | I31: 4.4 | J31: 0 | K31: Yes | L31: None | M31: Nature | N31: Yes | O31: 1.32 | P31: Morning
A32: 30 | B32: Southern | C32: Karnataka | D32: Bangalore | E32: Vidhana Soudha | F32: Government Building | G32: 1956 | H32: 0.5 | I32: 4.6 | J32: 0 | K32: Yes | L32: None | M32: Architectural | N32: No | O32: 0.8 | P32: Morning
A33: 31 | B33: Southern | C33: Karnataka | D33: Bangalore | E33: ISKCON Temple Bangalore | F33: Temple | G33: 1997 | H33: 1 | I33: 4.6 | J33: 0 | K33: Yes | L33: None | M33: Religious | N33: Yes | O33: 1.14 | P33: Evening
A34: 32 | B34: Southern | C34: Telangana | D34: Hyderabad | E34: Charminar | F34: Landmark | G34: 1591 | H34: 1 | I34: 4.5 | J34: 25 | K34: Yes | L34: Friday | M34: Historical | N34: Yes | O34: 2.1 | P34: Morning
A35: 33 | B35: Southern | C35: Telangana | D35: Hyderabad | E35: Golconda Fort | F35: Fort | G35: 1600 | H35: 2 | I35: 4.4 | J35: 30 | K35: Yes | L35: None | M35: Historical | N35: Yes | O35: 1.2 | P35: Morning
A36: 34 | B36: Southern | C36: Telangana | D36: Hyderabad | E36: Hussain Sagar Lake | F36: Lake | G36: 1563 | H36: 1 | I36: 4.3 | J36: 0 | K36: Yes | L36: None | M36: Scenic | N36: Yes | O36: 0.5 | P36: Evening
A37: 35 | B37: Southern | C37: Telangana | D37: Hyderabad | E37: Ramoji Film City | F37: Film Studio | G37: 1996 | H37: 4 | I37: 4.4 | J37: 1150 | K37: Yes | L37: None | M37: Entertainment | N37: Yes | O37: 0.45 | P37: All
... A53: 51 | B53: Eastern | C53: West Bengal | D53: Kolkata | E53: Marble Palace | F53: Palace | G53: 1835 | H53: 1 | I53: 4.4 | J53: 0 | K53: Yes | L53: None | M53: Historical | N53: Yes | O53: 0.1 | P53: Afternoon
A54: 52 | B54: Southern | C54: Goa | D54: Goa | E54: Calangute Beach | F54: Beach | G54: Unknown | H54: 2 | I54: 4.4 | J54: 0 | K54: Yes | L54: None | M54: Scenic | N54: Yes | O54: 0.26 | P54: Evening
A55: 53 | B55: Southern | C55: Goa | D55: Goa | E55: Basilica of Bom Jesus | F55: Church | G55: 1605 | H55: 1 | I55: 4.5 | J55: 0 | K55: Yes | L55: None | M55: Historical | N55: Yes | O55: 0.59 | P55: Afternoon
A56: 54 | B56: Southern | C56: Goa | D56: Goa | E56: Fort Aguada | F56: Fort | G56: 1612 | H56: 1.5 | I56: 4.2 | J56: 0 | K56: Yes | L56: None | M56: Historical | N56: Yes | O56: 0.95 | P56: Morning
A57: 55 | B57: Southern | C57: Goa | D57: Goa | E57: Dudhsagar Falls | F57: Waterfall | G57: Unknown | H57: 3 | I57: 4.6 | J57: 500 | K57: Yes | L57: None | M57: Nature | N57: Yes | O57: 0.3 | P57: Afternoon
A58: 56 | B58: Southern | C58: Goa | D58: Goa | E58: Anjuna Beach | F58: Beach | G58: Unknown | H58: 2 | I58: 4.4 | J58: 0 | K58: Yes | L58: None | M58: Scenic | N58: Yes | O58: 0.18 | P58: Evening
...

Sheet Cleaned Dataset
A1: Zone | B1: State | C1: City | D1: Name | E1: Type | F1: Establishment_Year | G1: Visit_Time_Hrs | H1: Reiew_Rating | I1: Rating_Category | J1: Entrance_Fee_INR | K1: Entry_Type | L1: Airport_50km_Radius | M1: Weekly_Off | N1: Significance | O1: DSLR_Allowed | P1: Number_Review_Lakhs | Q1: Best_Time_to_visit | R1: Popularity | S1: Visit_Duration | T1: Airport_Access | U1: Top_Rated | V1: Site Classification | W1: Column1 | X1: Star_rating | Y1: popularity_Traffic
A2: Northern | B2: Delhi | C2: Delhi | D2: India Gate | E2: War Memorial | F2: 1921 | G2: 0.5 | H2: 4.6 | I2: =IF(Table13[[#This Row],[Reiew_Rating]]>=4.5,"Excellent", IF(Table13[[#This Row],[Reiew_Rating]]>=4,"Good","Average")) -> Excellent | J2: 0 | K2: =IF(Table13[[#This Row],[Entrance_Fee_INR]]=0,"Free","Paid") -> Free | L2: Yes | M2: Friday | N2: Historical | O2: Yes | P2: 2.6 | Q2: Evening | R2: =IF(Table13[[#This Row],[Number_Review_Lakhs]]>=1,"Highly Popular", IF(Table13[[#This Row],[Number_Review_Lakhs]]>=0.5,"Popular","Less Popular")) -> Highly Popular | S2: =IF(Table13[[#This Row],[Visit_Time_Hrs]]<=2,"Short Visit", IF(Table13[[#This Row],[Visit_Time_Hrs]]<=5,"Medium Visit","Full Day")) -> Short Visit | T2: =IF(Table13[[#This Row],[Airport_50km_Radius]]="Yes","Accessible","Remote") -> Accessible | U2: =IF(Table13[[#This Row],[Reiew_Rating]]>=4.7,"Yes","No") -> No | V2: =IF(OR(N2="Historical",N2="Artistic",N2="Religious",N2="Architectural"), "Heritage & Culture", IF(OR(N2="Environmental",N2="Botanical",N2="Scenic",N2="Wildlife",N2="Nature"), "Nature & Wildlife", IF(OR(N2="Recreational",N2="Market",N2="Entertainment"), "Leisure & Commerce", IF(N2="Scientific", "Science & Education", "Other")))) -> Heritage & Culture | W2: =REPT("★", ROUND(H2, 0)) & REPT("☆", 5 - ROUND(H2, 0)) -> ★★★★★ | X2: =ROUND(H2, 0) & " / 5 Stars" -> 5 / 5 Stars | Y2: =IF(P2>=1.5, "High Traffic", IF(P2>=0.4, "Medium Traffic", "Low Traffic")) -> High Traffic
A3: Northern | B3: Delhi | C3: Delhi | D3: Humayun's Tomb | E3: Tomb | F3: 1572 | G3: 2 | H3: 4.5 | I3: =IF(Table13[[#This Row],[Reiew_Rating]]>=4.5,"Excellent", IF(Table13[[#This Row],[Reiew_Rating]]>=4,"Good","Average")) -> Excellent | J3: 30 | K3: =IF(Table13[[#This Row],[Entrance_Fee_INR]]=0,"Free","Paid") -> Paid | L3: Yes | M3: Friday | N3: Historical | O3: Yes | P3: 0.4 | Q3: Afternoon | R3: =IF(Table13[[#This Row],[Number_Review_Lakhs]]>=1,"Highly Popular", IF(Table13[[#This Row],[Number_Review_Lakhs]]>=0.5,"Popular","Less Popular")) -> Less Popular | S3: =IF(Table13[[#This Row],[Visit_Time_Hrs]]<=2,"Short Visit", IF(Table13[[#This Row],[Visit_Time_Hrs]]<=5,"Medium Visit","Full Day")) -> Short Visit | T3: =IF(Table13[[#This Row],[Airport_50km_Radius]]="Yes","Accessible","Remote") -> Accessible | U3: =IF(Table13[[#This Row],[Reiew_Rating]]>=4.7,"Yes","No") -> No | V3: =IF(OR(N3="Historical",N3="Artistic",N3="Religious",N3="Architectural"), "Heritage & Culture", IF(OR(N3="Environmental",N3="Botanical",N3="Scenic",N3="Wildlife",N3="Nature"), "Nature & Wildlife", IF(OR(N3="Recreational",N3="Market",N3="Entertainment"), "Leisure & Commerce", IF(N3="Scientific", "Science & Education", "Other")))) -> Heritage & Culture | W3: =REPT("★", ROUND(H3, 0)) & REPT("☆", 5 - ROUND(H3, 0)) -> ★★★★★ | X3: =ROUND(H3, 0) & " / 5 Stars" -> 5 / 5 Stars | Y3: =IF(P3>=1.5, "High Traffic", IF(P3>=0.4, "Medium Traffic", "Low Traffic")) -> Medium Traffic
A4: Northern | B4: Delhi | C4: Delhi | D4: Akshardham Temple | E4: Temple | F4: 2005 | G4: 5 | H4: 4.6 | I4: =IF(Table13[[#This Row],[Reiew_Rating]]>=4.5,"Excellent", IF(Table13[[#This Row],[Reiew_Rating]]>=4,"Good","Average")) -> Excellent | J4: 60 | K4: =IF(Table13[[#This Row],[Entrance_Fee_INR]]=0,"Free","Paid") -> Paid | L4: Yes | M4: Sunday | N4: Religious | O4: No | P4: 0.4 | Q4: Afternoon | R4: =IF(Table13[[#This Row],[Number_Review_Lakhs]]>=1,"Highly Popular", IF(Table13[[#This Row],[Number_Review_Lakhs]]>=0.5,"Popular","Less Popular")) -> Less Popular | S4: =IF(Table13[[#This Row],[Visit_Time_Hrs]]<=2,"Short Visit", IF(Table13[[#This Row],[Visit_Time_Hrs]]<=5,"Medium Visit","Full Day")) -> Medium Visit | T4: =IF(Table13[[#This Row],[Airport_50km_Radius]]="Yes","Accessible","Remote") -> Accessible | U4: =IF(Table13[[#This Row],[Reiew_Rating]]>=4.7,"Yes","No") -> No | V4: =IF(OR(N4="Historical",N4="Artistic",N4="Religious",N4="Architectural"), "Heritage & Culture", IF(OR(N4="Environmental",N4="Botanical",N4="Scenic",N4="Wildlife",N4="Nature"), "Nature & Wildlife", IF(OR(N4="Recreational",N4="Market",N4="Entertainment"), "Leisure & Commerce", IF(N4="Scientific", "Science & Education", "Other")))) -> Heritage & Culture | W4: =REPT("★", ROUND(H4, 0)) & REPT("☆", 5 - ROUND(H4, 0)) -> ★★★★★ | X4: =ROUND(H4, 0) & " / 5 Stars" -> 5 / 5 Stars | Y4: =IF(P4>=1.5, "High Traffic", IF(P4>=0.4, "Medium Traffic", "Low Traffic")) -> Medium Traffic
A5: Northern | B5: Delhi | C5: Delhi | D5: Waste to Wonder Park | E5: Theme Park | F5: 2019 | G5: 2 | H5: 4.1 | I5: =IF(Table13[[#This Row],[Reiew_Rating]]>=4.5,"Excellent", IF(Table13[[#This Row],[Reiew_Rating]]>=4,"Good","Average")) -> Good | J5: 50 | K5: =IF(Table13[[#This Row],[Entrance_Fee_INR]]=0,"Free","Paid") -> Paid | L5: Yes | M5: Monday | N5: Environmental | O5: Yes | P5: 0.27 | Q5: Evening | R5: =IF(Table13[[#This Row],[Number_Review_Lakhs]]>=1,"Highly Popular", IF(Table13[[#This Row],[Number_Review_Lakhs]]>=0.5,"Popular","Less Popular")) -> Less Popular | S5: =IF(Table13[[#This Row],[Visit_Time_Hrs]]<=2,"Short Visit", IF(Table13[[#This Row],[Visit_Time_Hrs]]<=5,"Medium Visit","Full Day")) -> Short Visit | T5: =IF(Table13[[#This Row],[Airport_50km_Radius]]="Yes","Accessible","Remote") -> Accessible | U5: =IF(Table13[[#This Row],[Reiew_Rating]]>=4.7,"Yes","No") -> No | V5: =IF(OR(N5="Historical",N5="Artistic",N5="Religious",N5="Architectural"), "Heritage & Culture", IF(OR(N5="Environmental",N5="Botanical",N5="Scenic",N5="Wildlife",N5="Nature"), "Nature & Wildlife", IF(OR(N5="Recreational",N5="Market",N5="Entertainment"), "Leisure & Commerce", IF(N5="Scientific", "Science & Education", "Other")))) -> Nature & Wildlife | W5: =REPT("★", ROUND(H5, 0)) & REPT("☆", 5 - ROUND(H5, 0)) -> ★★★★☆ | X5: =ROUND(H5, 0) & " / 5 Stars" -> 4 / 5 Stars | Y5: =IF(P5>=1.5, "High Traffic", IF(P5>=0.4, "Medium Traffic", "Low Traffic")) -> Low Traffic
A6: Northern | B6: Delhi | C6: Delhi | D6: Jantar Mantar | E6: Observatory | F6: 1724 | G6: 2 | H6: 4.2 | I6: =IF(Table13[[#This Row],[Reiew_Rating]]>=4.5,"Excellent", IF(Table13[[#This Row],[Reiew_Rating]]>=4,"Good","Average")) -> Good | J6: 15 | K6: =IF(Table13[[#This Row],[Entrance_Fee_INR]]=0,"Free","Paid") -> Paid | L6: Yes | M6: Sunday | N6: Scientific | O6: Yes | P6: 0.31 | Q6: Morning | R6: =IF(Table13[[#This Row],[Number_Review_Lakhs]]>=1,"Highly Popular", IF(Table13[[#This Row],[Number_Review_Lakhs]]>=0.5,"Popular","Less Popular")) -> Less Popular | S6: =IF(Table13[[#This Row],[Visit_Time_Hrs]]<=2,"Short Visit", IF(Table13[[#This Row],[Visit_Time_Hrs]]<=5,"Medium Visit","Full Day")) -> Short Visit | T6: =IF(Table13[[#This Row],[Airport_50km_Radius]]="Yes","Accessible","Remote") -> Accessible | U6: =IF(Table13[[#This Row],[Reiew_Rating]]>=4.7,"Yes","No") -> No | V6: =IF(OR(N6="Historical",N6="Artistic",N6="Religious",N6="Architectural"), "Heritage & Culture", IF(OR(N6="Environmental",N6="Botanical",N6="Scenic",N6="Wildlife",N6="Nature"), "Nature & Wildlife", IF(OR(N6="Recreational",N6="Market",N6="Entertainment"), "Leisure & Commerce", IF(N6="Scientific", "Science & Education", "Other")))) -> Science & Education | W6: =REPT("★", ROUND(H6, 0)) & REPT("☆", 5 - ROUND(H6, 0)) -> ★★★★☆ | X6: =ROUND(H6, 0) & " / 5 Stars" -> 4 / 5 Stars | Y6: =IF(P6>=1.5, "High Traffic", IF(P6>=0.4, "Medium Traffic", "Low Traffic")) -> Low Traffic
A7: Northern | B7: Delhi | C7: Delhi | D7: Chandni Chowk | E7: Market | F7: 1700 | G7: 3 | H7: 4.2 | I7: =IF(Table13[[#This Row],[Reiew_Rating]]>=4.5,"Excellent", IF(Table13[[#This Row],[Reiew_Rating]]>=4,"Good","Average")) -> Good | J7: 0 | K7: =IF(Table13[[#This Row],[Entrance_Fee_INR]]=0,"Free","Paid") -> Free | L7: Yes | M7: Sunday | N7: Market | O7: Yes | P7: 0.25 | Q7: Afternoon | R7: =IF(Table13[[#This Row],[Number_Review_Lakhs]]>=1,"Highly Popular", IF(Table13[[#This Row],[Number_Review_Lakhs]]>=0.5,"Popular","Less Popular")) -> Less Popular | S7: =IF(Table13[[#This Row],[Visit_Time_Hrs]]<=2,"Short Visit", IF(Table13[[#This Row],[Visit_Time_Hrs]]<=5,"Medium Visit","Full Day")) -> Medium Visit | T7: =IF(Table13[[#This Row],[Airport_50km_Radius]]="Yes","Accessible","Remote") -> Accessible | U7: =IF(Table13[[#This Row],[Reiew_Rating]]>=4.7,"Yes","No") -> No | V7: =IF(OR(N7="Historical",N7="Artistic",N7="Religious",N7="Architectural"), "Heritage & Culture", IF(OR(N7="Environmental",N7="Botanical",N7="Scenic",N7="Wildlife",N7="Nature"), "Nature & Wildlife", IF(OR(N7="Recreational",N7="Market",N7="Entertainment"), "Leisure & Commerce", IF(N7="Scientific", "Science & Education", "Other")))) -> Leisure & Commerce | W7: =REPT("★", ROUND(H7, 0)) & REPT("☆", 5 - ROUND(H7, 0)) -> ★★★★☆ | X7: =ROUND(H7, 0) & " / 5 Stars" -> 4 / 5 Stars | Y7: =IF(P7>=1.5, "High Traffic", IF(P7>=0.4, "Medium Traffic", "Low Traffic")) -> Low Traffic
A8: Northern | B8: Delhi | C8: Delhi | D8: Lotus Temple | E8: Temple | F8: 1986 | G8: 1 | H8: 4.5 | I8: =IF(Table13[[#This Row],[Reiew_Rating]]>=4.5,"Excellent", IF(Table13[[#This Row],[Reiew_Rating]]>=4,"Good","Average")) -> Excellent | J8: 0 | K8: =IF(Table13[[#This Row],[Entrance_Fee_INR]]=0,"Free","Paid") -> Free | L8: Yes | M8: Monday | N8: Religious | O8: Yes | P8: 0.59 | Q8: Evening | R8: =IF(Table13[[#This Row],[Number_Review_Lakhs]]>=1,"Highly Popular", IF(Table13[[#This Row],[Number_Review_Lakhs]]>=0.5,"Popular","Less Popular")) -> Popular | S8: =IF(Table13[[#This Row],[Visit_Time_Hrs]]<=2,"Short Visit", IF(Table13[[#This Row],[Visit_Time_Hrs]]<=5,"Medium Visit","Full Day")) -> Short Visit | T8: =IF(Table13[[#This Row],[Airport_50km_Radius]]="Yes","Accessible","Remote") -> Accessible | U8: =IF(Table13[[#This Row],[Reiew_Rating]]>=4.7,"Yes","No") -> No | V8: =IF(OR(N8="Historical",N8="Artistic",N8="Religious",N8="Architectural"), "Heritage & Culture", IF(OR(N8="Environmental",N8="Botanical",N8="Scenic",N8="Wildlife",N8="Nature"), "Nature & Wildlife", IF(OR(N8="Recreational",N8="Market",N8="Entertainment"), "Leisure & Commerce", IF(N8="Scientific", "Science & Education", "Other")))) -> Heritage & Culture | W8: =REPT("★", ROUND(H8, 0)) & REPT("☆", 5 - ROUND(H8, 0)) -> ★★★★★ | X8: =ROUND(H8, 0) & " / 5 Stars" -> 5 / 5 Stars | Y8: =IF(P8>=1.5, "High Traffic", IF(P8>=0.4, "Medium Traffic", "Low Traffic")) -> Medium Traffic
A9: Northern | B9: Delhi | C9: Delhi | D9: Red Fort | E9: Fort | F9: 1648 | G9: 2 | H9: 4.5 | I9: =IF(Table13[[#This Row],[Reiew_Rating]]>=4.5,"Excellent", IF(Table13[[#This Row],[Reiew_Rating]]>=4,"Good","Average")) -> Excellent | J9: 35 | K9: =IF(Table13[[#This Row],[Entrance_Fee_INR]]=0,"Free","Paid") -> Paid | L9: Yes | M9: Tuesday | N9: Historical | O9: Yes | P9: 1.5 | Q9: Afternoon | R9: =IF(Table13[[#This Row],[Number_Review_Lakhs]]>=1,"Highly Popular", IF(Table13[[#This Row],[Number_Review_Lakhs]]>=0.5,"Popular","Less Popular")) -> Highly Popular | S9: =IF(Table13[[#This Row],[Visit_Time_Hrs]]<=2,"Short Visit", IF(Table13[[#This Row],[Visit_Time_Hrs]]<=5,"Medium Visit","Full Day")) -> Short Visit | T9: =IF(Table13[[#This Row],[Airport_50km_Radius]]="Yes","Accessible","Remote") -> Accessible | U9: =IF(Table13[[#This Row],[Reiew_Rating]]>=4.7,"Yes","No") -> No | V9: =IF(OR(N9="Historical",N9="Artistic",N9="Religious",N9="Architectural"), "Heritage & Culture", IF(OR(N9="Environmental",N9="Botanical",N9="Scenic",N9="Wildlife",N9="Nature"), "Nature & Wildlife", IF(OR(N9="Recreational",N9="Market",N9="Entertainment"), "Leisure & Commerce", IF(N9="Scientific", "Science & Education", "Other")))) -> Heritage & Culture | W9: =REPT("★", ROUND(H9, 0)) & REPT("☆", 5 - ROUND(H9, 0)) -> ★★★★★ | X9: =ROUND(H9, 0) & " / 5 Stars" -> 5 / 5 Stars | Y9: =IF(P9>=1.5, "High Traffic", IF(P9>=0.4, "Medium Traffic", "Low Traffic")) -> High Traffic
A10: Northern | B10: Delhi | C10: Delhi | D10: Agrasen ki Baoli | E10: Stepwell | F10: 1400 | G10: 1 | H10: 4.2 | I10: =IF(Table13[[#This Row],[Reiew_Rating]]>=4.5,"Excellent", IF(Table13[[#This Row],[Reiew_Rating]]>=4,"Good","Average")) -> Good | J10: 0 | K10: =IF(Table13[[#This Row],[Entrance_Fee_INR]]=0,"Free","Paid") -> Free | L10: Yes | M10: Wednesday | N10: Historical | O10: Yes | P10: 0.41 | Q10: Afternoon | R10: =IF(Table13[[#This Row],[Number_Review_Lakhs]]>=1,"Highly Popular", IF(Table13[[#This Row],[Number_Review_Lakhs]]>=0.5,"Popular","Less Popular")) -> Less Popular | S10: =IF(Table13[[#This Row],[Visit_Time_Hrs]]<=2,"Short Visit", IF(Table13[[#This Row],[Visit_Time_Hrs]]<=5,"Medium Visit","Full Day")) -> Short Visit | T10: =IF(Table13[[#This Row],[Airport_50km_Radius]]="Yes","Accessible","Remote") -> Accessible | U10: =IF(Table13[[#This Row],[Reiew_Rating]]>=4.7,"Yes","No") -> No | V10: =IF(OR(N10="Historical",N10="Artistic",N10="Religious",N10="Architectural"), "Heritage & Culture", IF(OR(N10="Environmental",N10="Botanical",N10="Scenic",N10="Wildlife",N10="Nature"), "Nature & Wildlife", IF(OR(N10="Recreational",N10="Market",N10="Entertainment"), "Leisure & Commerce", IF(N10="Scientific", "Science & Education", "Other")))) -> Heritage & Culture | W10: =REPT("★", ROUND(H10, 0)) & REPT("☆", 5 - ROUND(H10, 0)) -> ★★★★☆ | X10: =ROUND(H10, 0) & " / 5 Stars" -> 4 / 5 Stars | Y10: =IF(P10>=1.5, "High Traffic", IF(P10>=0.4, "Medium Traffic", "Low Traffic")) -> Medium Traffic
A11: Northern | B11: Delhi | C11: Delhi | D11: Sunder Nursery | E11: Park | F11: 1600 | G11: 2 | H11: 4.6 | I11: =IF(Table13[[#This Row],[Reiew_Rating]]>=4.5,"Excellent", IF(Table13[[#This Row],[Reiew_Rating]]>=4,"Good","Average")) -> Excellent | J11: 0 | K11: =IF(Table13[[#This Row],[Entrance_Fee_INR]]=0,"Free","Paid") -> Free | L11: Yes | M11: Wednesday | N11: Botanical | O11: Yes | P11: 0.16 | Q11: Afternoon | R11: =IF(Table13[[#This Row],[Number_Review_Lakhs]]>=1,"Highly Popular", IF(Table13[[#This Row],[Number_Review_Lakhs]]>=0.5,"Popular","Less Popular")) -> Less Popular | S11: =IF(Table13[[#This Row],[Visit_Time_Hrs]]<=2,"Short Visit", IF(Table13[[#This Row],[Visit_Time_Hrs]]<=5,"Medium Visit","Full Day")) -> Short Visit | T11: =IF(Table13[[#This Row],[Airport_50km_Radius]]="Yes","Accessible","Remote") -> Accessible | U11: =IF(Table13[[#This Row],[Reiew_Rating]]>=4.7,"Yes","No") -> No | V11: =IF(OR(N11="Historical",N11="Artistic",N11="Religious",N11="Architectural"), "Heritage & Culture", IF(OR(N11="Environmental",N11="Botanical",N11="Scenic",N11="Wildlife",N11="Nature"), "Nature & Wildlife", IF(OR(N11="Recreational",N11="Market",N11="Entertainment"), "Leisure & Commerce", IF(N11="Scientific", "Science & Education", "Other")))) -> Nature & Wildlife | W11: =REPT("★", ROUND(H11, 0)) & REPT("☆", 5 - ROUND(H11, 0)) -> ★★★★★ | X11: =ROUND(H11, 0) & " / 5 Stars" -> 5 / 5 Stars | Y11: =IF(P11>=1.5, "High Traffic", IF(P11>=0.4, "Medium Traffic", "Low Traffic")) -> Low Traffic
A12: Northern | B12: Delhi | C12: Delhi | D12: Garden of Five Senses | E12: Park | F12: 2003 | G12: 2 | H12: 4.1 | I12: =IF(Table13[[#This Row],[Reiew_Rating]]>=4.5,"Excellent", IF(Table13[[#This Row],[Reiew_Rating]]>=4,"Good","Average")) -> Good | J12: 35 | K12: =IF(Table13[[#This Row],[Entrance_Fee_INR]]=0,"Free","Paid") -> Paid | L12: Yes | M12: Friday | N12: Botanical | O12: Yes | P12: 0.23 | Q12: Morning | R12: =IF(Table13[[#This Row],[Number_Review_Lakhs]]>=1,"Highly Popular", IF(Table13[[#This Row],[Number_Review_Lakhs]]>=0.5,"Popular","Less Popular")) -> Less Popular | S12: =IF(Table13[[#This Row],[Visit_Time_Hrs]]<=2,"Short Visit", IF(Table13[[#This Row],[Visit_Time_Hrs]]<=5,"Medium Visit","Full Day")) -> Short Visit | T12: =IF(Table13[[#This Row],[Airport_50km_Radius]]="Yes","Accessible","Remote") -> Accessible | U12: =IF(Table13[[#This Row],[Reiew_Rating]]>=4.7,"Yes","No") -> No | V12: =IF(OR(N12="Historical",N12="Artistic",N12="Religious",N12="Architectural"), "Heritage & Culture", IF(OR(N12="Environmental",N12="Botanical",N12="Scenic",N12="Wildlife",N12="Nature"), "Nature & Wildlife", IF(OR(N12="Recreational",N12="Market",N12="Entertainment"), "Leisure & Commerce", IF(N12="Scientific", "Science & Education", "Other")))) -> Nature & Wildlife | W12: =REPT("★", ROUND(H12, 0)) & REPT("☆", 5 - ROUND(H12, 0)) -> ★★★★☆ | X12: =ROUND(H12, 0) & " / 5 Stars" -> 4 / 5 Stars | Y12: =IF(P12>=1.5, "High Traffic", IF(P12>=0.4, "Medium Traffic", "Low Traffic")) -> Low Traffic
A13: Northern | B13: Delhi | C13: Delhi | D13: Lodhi Garden | E13: Park | F13: 1500 | G13: 1 | H13: 4.5 | I13: =IF(Table13[[#This Row],[Reiew_Rating]]>=4.5,"Excellent", IF(Table13[[#This Row],[Reiew_Rating]]>=4,"Good","Average")) -> Excellent | J13: 0 | K13: =IF(Table13[[#This Row],[Entrance_Fee_INR]]=0,"Free","Paid") -> Free | L13: Yes | M13: Thursday | N13: Botanical | O13: Yes | P13: 0.48 | Q13: All | R13: =IF(Table13[[#This Row],[Number_Review_Lakhs]]>=1,"Highly Popular", IF(Table13[[#This Row],[Number_Review_Lakhs]]>=0.5,"Popular","Less Popular")) -> Less Popular | S13: =IF(Table13[[#This Row],[Visit_Time_Hrs]]<=2,"Short Visit", IF(Table13[[#This Row],[Visit_Time_Hrs]]<=5,"Medium Visit","Full Day")) -> Short Visit | T13: =IF(Table13[[#This Row],[Airport_50km_Radius]]="Yes","Accessible","Remote") -> Accessible | U13: =IF(Table13[[#This Row],[Reiew_Rating]]>=4.7,"Yes","No") -> No | V13: =IF(OR(N13="Historical",N13="Artistic",N13="Religious",N13="Architectural"), "Heritage & Culture", IF(OR(N13="Environmental",N13="Botanical",N13="Scenic",N13="Wildlife",N13="Nature"), "Nature & Wildlife", IF(OR(N13="Recreational",N13="Market",N13="Entertainment"), "Leisure & Commerce", IF(N13="Scientific", "Science & Education", "Other")))) -> Nature & Wildlife | W13: =REPT("★", ROUND(H13, 0)) & REPT("☆", 5 - ROUND(H13, 0)) -> ★★★★★ | X13: =ROUND(H13, 0) & " / 5 Stars" -> 5 / 5 Stars | Y13: =IF(P13>=1.5, "High Traffic", IF(P13>=0.4, "Medium Traffic", "Low Traffic")) -> Medium Traffic
... A226: Eastern | B226: West Bengal | C226: Purulia | D226: Ayodhya Hills | E226: Hill | F226: 1719 | G226: 2.5 | H226: 4.5 | I226: =IF(Table13[[#This Row],[Reiew_Rating]]>=4.5,"Excellent", IF(Table13[[#This Row],[Reiew_Rating]]>=4,"Good","Average")) -> Excellent | J226: 0 | K226: =IF(Table13[[#This Row],[Entrance_Fee_INR]]=0,"Free","Paid") -> Free | L226: No | M226: Wednesday | N226: Nature | O226: Yes | P226: 0.15 | Q226: All | R226: =IF(Table13[[#This Row],[Number_Review_Lakhs]]>=1,"Highly Popular", IF(Table13[[#This Row],[Number_Review_Lakhs]]>=0.5,"Popular","Less Popular")) -> Less Popular | S226: =IF(Table13[[#This Row],[Visit_Time_Hrs]]<=2,"Short Visit", IF(Table13[[#This Row],[Visit_Time_Hrs]]<=5,"Medium Visit","Full Day")) -> Medium Visit | T226: =IF(Table13[[#This Row],[Airport_50km_Radius]]="Yes","Accessible","Remote") -> Remote | U226: =IF(Table13[[#This Row],[Reiew_Rating]]>=4.7,"Yes","No") -> No | V226: =IF(OR(N226="Historical",N226="Artistic",N226="Religious",N226="Architectural"), "Heritage & Culture", IF(OR(N226="Environmental",N226="Botanical",N226="Scenic",N226="Wildlife",N226="Nature"), "Nature & Wildlife", IF(OR(N226="Recreational",N226="Market",N226="Entertainment"), "Leisure & Commerce", IF(N226="Scientific", "Science & Education", "Other")))) -> Nature & Wildlife | W226: =REPT("★", ROUND(H226, 0)) & REPT("☆", 5 - ROUND(H226, 0)) -> ★★★★★ | X226: =ROUND(H226, 0) & " / 5 Stars" -> 5 / 5 Stars | Y226: =IF(P226>=1.5, "High Traffic", IF(P226>=0.4, "Medium Traffic", "Low Traffic")) -> Low Traffic
A227: Eastern | B227: Odisha | C227: Puri | D227: Jagannath Temple | E227: Temple | F227: 12th century | G227: 2 | H227: 4.7 | I227: =IF(Table13[[#This Row],[Reiew_Rating]]>=4.5,"Excellent", IF(Table13[[#This Row],[Reiew_Rating]]>=4,"Good","Average")) -> Excellent | J227: 0 | K227: =IF(Table13[[#This Row],[Entrance_Fee_INR]]=0,"Free","Paid") -> Free | L227: Yes | M227: Sunday | N227: Religious | O227: No | P227: 1 | Q227: All | R227: =IF(Table13[[#This Row],[Number_Review_Lakhs]]>=1,"Highly Popular", IF(Table13[[#This Row],[Number_Review_Lakhs]]>=0.5,"Popular","Less Popular")) -> Highly Popular | S227: =IF(Table13[[#This Row],[Visit_Time_Hrs]]<=2,"Short Visit", IF(Table13[[#This Row],[Visit_Time_Hrs]]<=5,"Medium Visit","Full Day")) -> Short Visit | T227: =IF(Table13[[#This Row],[Airport_50km_Radius]]="Yes","Accessible","Remote") -> Accessible | U227: =IF(Table13[[#This Row],[Reiew_Rating]]>=4.7,"Yes","No") -> Yes | V227: =IF(OR(N227="Historical",N227="Artistic",N227="Religious",N227="Architectural"), "Heritage & Culture", IF(OR(N227="Environmental",N227="Botanical",N227="Scenic",N227="Wildlife",N227="Nature"), "Nature & Wildlife", IF(OR(N227="Recreational",N227="Market",N227="Entertainment"), "Leisure & Commerce", IF(N227="Scientific", "Science & Education", "Other")))) -> Heritage & Culture | W227: =REPT("★", ROUND(H227, 0)) & REPT("☆", 5 - ROUND(H227, 0)) -> ★★★★★ | X227: =ROUND(H227, 0) & " / 5 Stars" -> 5 / 5 Stars | Y227: =IF(P227>=1.5, "High Traffic", IF(P227>=0.4, "Medium Traffic", "Low Traffic")) -> Medium Traffic
A228: Eastern | B228: Odisha | C228: Konark | D228: Sun Temple | E228: Temple | F228: 1250 | G228: 1.5 | H228: 4.7 | I228: =IF(Table13[[#This Row],[Reiew_Rating]]>=4.5,"Excellent", IF(Table13[[#This Row],[Reiew_Rating]]>=4,"Good","Average")) -> Excellent | J228: 40 | K228: =IF(Table13[[#This Row],[Entrance_Fee_INR]]=0,"Free","Paid") -> Paid | L228: Yes | M228: Wednesday | N228: Historical | O228: Yes | P228: 0.83 | Q228: All | R228: =IF(Table13[[#This Row],[Number_Review_Lakhs]]>=1,"Highly Popular", IF(Table13[[#This Row],[Number_Review_Lakhs]]>=0.5,"Popular","Less Popular")) -> Popular | S228: =IF(Table13[[#This Row],[Visit_Time_Hrs]]<=2,"Short Visit", IF(Table13[[#This Row],[Visit_Time_Hrs]]<=5,"Medium Visit","Full Day")) -> Short Visit | T228: =IF(Table13[[#This Row],[Airport_50km_Radius]]="Yes","Accessible","Remote") -> Accessible | U228: =IF(Table13[[#This Row],[Reiew_Rating]]>=4.7,"Yes","No") -> Yes | V228: =IF(OR(N228="Historical",N228="Artistic",N228="Religious",N228="Architectural"), "Heritage & Culture", IF(OR(N228="Environmental",N228="Botanical",N228="Scenic",N228="Wildlife",N228="Nature"), "Nature & Wildlife", IF(OR(N228="Recreational",N228="Market",N228="Entertainment"), "Leisure & Commerce", IF(N228="Scientific", "Science & Education", "Other")))) -> Heritage & Culture | W228: =REPT("★", ROUND(H228, 0)) & REPT("☆", 5 - ROUND(H228, 0)) -> ★★★★★ | X228: =ROUND(H228, 0) & " / 5 Stars" -> 5 / 5 Stars | Y228: =IF(P228>=1.5, "High Traffic", IF(P228>=0.4, "Medium Traffic", "Low Traffic")) -> Medium Traffic
A229: Eastern | B229: Odisha | C229: Bhubaneswar | D229: Lingaraj Temple | E229: Temple | F229: 11th century | G229: 1 | H229: 4.6 | I229: =IF(Table13[[#This Row],[Reiew_Rating]]>=4.5,"Excellent", IF(Table13[[#This Row],[Reiew_Rating]]>=4,"Good","Average")) -> Excellent | J229: 0 | K229: =IF(Table13[[#This Row],[Entrance_Fee_INR]]=0,"Free","Paid") -> Free | L229: Yes | M229: Friday | N229: Religious | O229: No | P229: 0.35 | Q229: All | R229: =IF(Table13[[#This Row],[Number_Review_Lakhs]]>=1,"Highly Popular", IF(Table13[[#This Row],[Number_Review_Lakhs]]>=0.5,"Popular","Less Popular")) -> Less Popular | S229: =IF(Table13[[#This Row],[Visit_Time_Hrs]]<=2,"Short Visit", IF(Table13[[#This Row],[Visit_Time_Hrs]]<=5,"Medium Visit","Full Day")) -> Short Visit | T229: =IF(Table13[[#This Row],[Airport_50km_Radius]]="Yes","Accessible","Remote") -> Accessible | U229: =IF(Table13[[#This Row],[Reiew_Rating]]>=4.7,"Yes","No") -> No | V229: =IF(OR(N229="Historical",N229="Artistic",N229="Religious",N229="Architectural"), "Heritage & Culture", IF(OR(N229="Environmental",N229="Botanical",N229="Scenic",N229="Wildlife",N229="Nature"), "Nature & Wildlife", IF(OR(N229="Recreational",N229="Market",N229="Entertainment"), "Leisure & Commerce", IF(N229="Scientific", "Science & Education", "Other")))) -> Heritage & Culture | W229: =REPT("★", ROUND(H229, 0)) & REPT("☆", 5 - ROUND(H229, 0)) -> ★★★★★ | X229: =ROUND(H229, 0) & " / 5 Stars" -> 5 / 5 Stars | Y229: =IF(P229>=1.5, "High Traffic", IF(P229>=0.4, "Medium Traffic", "Low Traffic")) -> Low Traffic
A230: Eastern | B230: Odisha | C230: Rourkela | D230: Khandadhar Waterfall | E230: Waterfall | F230: 1774 | G230: 1.5 | H230: 4.5 | I230: =IF(Table13[[#This Row],[Reiew_Rating]]>=4.5,"Excellent", IF(Table13[[#This Row],[Reiew_Rating]]>=4,"Good","Average")) -> Excellent | J230: 0 | K230: =IF(Table13[[#This Row],[Entrance_Fee_INR]]=0,"Free","Paid") -> Free | L230: No | M230: Sunday | N230: Nature | O230: Yes | P230: 1.2 | Q230: All | R230: =IF(Table13[[#This Row],[Number_Review_Lakhs]]>=1,"Highly Popular", IF(Table13[[#This Row],[Number_Review_Lakhs]]>=0.5,"Popular","Less Popular")) -> Highly Popular | S230: =IF(Table13[[#This Row],[Visit_Time_Hrs]]<=2,"Short Visit", IF(Table13[[#This Row],[Visit_Time_Hrs]]<=5,"Medium Visit","Full Day")) -> Short Visit | T230: =IF(Table13[[#This Row],[Airport_50km_Radius]]="Yes","Accessible","Remote") -> Remote | U230: =IF(Table13[[#This Row],[Reiew_Rating]]>=4.7,"Yes","No") -> No | V230: =IF(OR(N230="Historical",N230="Artistic",N230="Religious",N230="Architectural"), "Heritage & Culture", IF(OR(N230="Environmental",N230="Botanical",N230="Scenic",N230="Wildlife",N230="Nature"), "Nature & Wildlife", IF(OR(N230="Recreational",N230="Market",N230="Entertainment"), "Leisure & Commerce", IF(N230="Scientific", "Science & Education", "Other")))) -> Nature & Wildlife | W230: =REPT("★", ROUND(H230, 0)) & REPT("☆", 5 - ROUND(H230, 0)) -> ★★★★★ | X230: =ROUND(H230, 0) & " / 5 Stars" -> 5 / 5 Stars | Y230: =IF(P230>=1.5, "High Traffic", IF(P230>=0.4, "Medium Traffic", "Low Traffic")) -> Medium Traffic
A231: Eastern | B231: Odisha | C231: Cuttack | D231: Barabati Fort | E231: Fort | F231: -987 | G231: 1 | H231: 4.5 | I231: =IF(Table13[[#This Row],[Reiew_Rating]]>=4.5,"Excellent", IF(Table13[[#This Row],[Reiew_Rating]]>=4,"Good","Average")) -> Excellent | J231: 0 | K231: =IF(Table13[[#This Row],[Entrance_Fee_INR]]=0,"Free","Paid") -> Free | L231: Yes | M231: Saturday | N231: Historical | O231: Yes | P231: 0.13 | Q231: All | R231: =IF(Table13[[#This Row],[Number_Review_Lakhs]]>=1,"Highly Popular", IF(Table13[[#This Row],[Number_Review_Lakhs]]>=0.5,"Popular","Less Popular")) -> Less Popular | S231: =IF(Table13[[#This Row],[Visit_Time_Hrs]]<=2,"Short Visit", IF(Table13[[#This Row],[Visit_Time_Hrs]]<=5,"Medium Visit","Full Day")) -> Short Visit | T231: =IF(Table13[[#This Row],[Airport_50km_Radius]]="Yes","Accessible","Remote") -> Accessible | U231: =IF(Table13[[#This Row],[Reiew_Rating]]>=4.7,"Yes","No") -> No | V231: =IF(OR(N231="Historical",N231="Artistic",N231="Religious",N231="Architectural"), "Heritage & Culture", IF(OR(N231="Environmental",N231="Botanical",N231="Scenic",N231="Wildlife",N231="Nature"), "Nature & Wildlife", IF(OR(N231="Recreational",N231="Market",N231="Entertainment"), "Leisure & Commerce", IF(N231="Scientific", "Science & Education", "Other")))) -> Heritage & Culture | W231: =REPT("★", ROUND(H231, 0)) & REPT("☆", 5 - ROUND(H231, 0)) -> ★★★★★ | X231: =ROUND(H231, 0) & " / 5 Stars" -> 5 / 5 Stars | Y231: =IF(P231>=1.5, "High Traffic", IF(P231>=0.4, "Medium Traffic", "Low Traffic")) -> Low Traffic
A232: Eastern | B232: Odisha | C232: Sambalpur | D232: Hirakud Dam | E232: Dam | F232: 1957 | G232: 1 | H232: 4.5 | I232: =IF(Table13[[#This Row],[Reiew_Rating]]>=4.5,"Excellent", IF(Table13[[#This Row],[Reiew_Rating]]>=4,"Good","Average")) -> Excellent | J232: 0 | K232: =IF(Table13[[#This Row],[Entrance_Fee_INR]]=0,"Free","Paid") -> Free | L232: No | M232: Monday | N232: Engineering Marvel | O232: Yes | P232: 0.01 | Q232: All | R232: =IF(Table13[[#This Row],[Number_Review_Lakhs]]>=1,"Highly Popular", IF(Table13[[#This Row],[Number_Review_Lakhs]]>=0.5,"Popular","Less Popular")) -> Less Popular | S232: =IF(Table13[[#This Row],[Visit_Time_Hrs]]<=2,"Short Visit", IF(Table13[[#This Row],[Visit_Time_Hrs]]<=5,"Medium Visit","Full Day")) -> Short Visit | T232: =IF(Table13[[#This Row],[Airport_50km_Radius]]="Yes","Accessible","Remote") -> Remote | U232: =IF(Table13[[#This Row],[Reiew_Rating]]>=4.7,"Yes","No") -> No | V232: =IF(OR(N232="Historical",N232="Artistic",N232="Religious",N232="Architectural"), "Heritage & Culture", IF(OR(N232="Environmental",N232="Botanical",N232="Scenic",N232="Wildlife",N232="Nature"), "Nature & Wildlife", IF(OR(N232="Recreational",N232="Market",N232="Entertainment"), "Leisure & Commerce", IF(N232="Scientific", "Science & Education", "Other")))) -> Other | W232: =REPT("★", ROUND(H232, 0)) & REPT("☆", 5 - ROUND(H232, 0)) -> ★★★★★ | X232: =ROUND(H232, 0) & " / 5 Stars" -> 5 / 5 Stars | Y232: =IF(P232>=1.5, "High Traffic", IF(P232>=0.4, "Medium Traffic", "Low Traffic")) -> Low Traffic
A233: Eastern | B233: Odisha | C233: Chilika | D233: Chilika Lake | E233: Lake | F233: 1497 | G233: 2 | H233: 3.9 | I233: =IF(Table13[[#This Row],[Reiew_Rating]]>=4.5,"Excellent", IF(Table13[[#This Row],[Reiew_Rating]]>=4,"Good","Average")) -> Average | J233: 0 | K233: =IF(Table13[[#This Row],[Entrance_Fee_INR]]=0,"Free","Paid") -> Free | L233: Yes | M233: Sunday | N233: Nature | O233: Yes | P233: 0.1 | Q233: Morning | R233: =IF(Table13[[#This Row],[Number_Review_Lakhs]]>=1,"Highly Popular", IF(Table13[[#This Row],[Number_Review_Lakhs]]>=0.5,"Popular","Less Popular")) -> Less Popular | S233: =IF(Table13[[#This Row],[Visit_Time_Hrs]]<=2,"Short Visit", IF(Table13[[#This Row],[Visit_Time_Hrs]]<=5,"Medium Visit","Full Day")) -> Short Visit | T233: =IF(Table13[[#This Row],[Airport_50km_Radius]]="Yes","Accessible","Remote") -> Accessible | U233: =IF(Table13[[#This Row],[Reiew_Rating]]>=4.7,"Yes","No") -> No | V233: =IF(OR(N233="Historical",N233="Artistic",N233="Religious",N233="Architectural"), "Heritage & Culture", IF(OR(N233="Environmental",N233="Botanical",N233="Scenic",N233="Wildlife",N233="Nature"), "Nature & Wildlife", IF(OR(N233="Recreational",N233="Market",N233="Entertainment"), "Leisure & Commerce", IF(N233="Scientific", "Science & Education", "Other")))) -> Nature & Wildlife | W233: =REPT("★", ROUND(H233, 0)) & REPT("☆", 5 - ROUND(H233, 0)) -> ★★★★☆ | X233: =ROUND(H233, 0) & " / 5 Stars" -> 4 / 5 Stars | Y233: =IF(P233>=1.5, "High Traffic", IF(P233>=0.4, "Medium Traffic", "Low Traffic")) -> Low Traffic
A234: Eastern | B234: Odisha | C234: Berhampur | D234: Tara Tarini Temple | E234: Temple | F234: Ancient | G234: 1 | H234: 4.6 | I234: =IF(Table13[[#This Row],[Reiew_Rating]]>=4.5,"Excellent", IF(Table13[[#This Row],[Reiew_Rating]]>=4,"Good","Average")) -> Excellent | J234: 0 | K234: =IF(Table13[[#This Row],[Entrance_Fee_INR]]=0,"Free","Paid") -> Free | L234: Yes | M234: Sunday | N234: Religious | O234: No | P234: 0.01 | Q234: All | R234: =IF(Table13[[#This Row],[Number_Review_Lakhs]]>=1,"Highly Popular", IF(Table13[[#This Row],[Number_Review_Lakhs]]>=0.5,"Popular","Less Popular")) -> Less Popular | S234: =IF(Table13[[#This Row],[Visit_Time_Hrs]]<=2,"Short Visit", IF(Table13[[#This Row],[Visit_Time_Hrs]]<=5,"Medium Visit","Full Day")) -> Short Visit | T234: =IF(Table13[[#This Row],[Airport_50km_Radius]]="Yes","Accessible","Remote") -> Accessible | U234: =IF(Table13[[#This Row],[Reiew_Rating]]>=4.7,"Yes","No") -> No | V234: =IF(OR(N234="Historical",N234="Artistic",N234="Religious",N234="Architectural"), "Heritage & Culture", IF(OR(N234="Environmental",N234="Botanical",N234="Scenic",N234="Wildlife",N234="Nature"), "Nature & Wildlife", IF(OR(N234="Recreational",N234="Market",N234="Entertainment"), "Leisure & Commerce", IF(N234="Scientific", "Science & Education", "Other")))) -> Heritage & Culture | W234: =REPT("★", ROUND(H234, 0)) & REPT("☆", 5 - ROUND(H234, 0)) -> ★★★★★ | X234: =ROUND(H234, 0) & " / 5 Stars" -> 5 / 5 Stars | Y234: =IF(P234>=1.5, "High Traffic", IF(P234>=0.4, "Medium Traffic", "Low Traffic")) -> Low Traffic
A235: Eastern | B235: Odisha | C235: Keonjhar | D235: Badaghagara Waterfall | E235: Waterfall | F235: 1674 | G235: 1 | H235: 4.3 | I235: =IF(Table13[[#This Row],[Reiew_Rating]]>=4.5,"Excellent", IF(Table13[[#This Row],[Reiew_Rating]]>=4,"Good","Average")) -> Good | J235: 0 | K235: =IF(Table13[[#This Row],[Entrance_Fee_INR]]=0,"Free","Paid") -> Free | L235: No | M235: Tuesday | N235: Nature | O235: Yes | P235: 0.018 | Q235: Morning | R235: =IF(Table13[[#This Row],[Number_Review_Lakhs]]>=1,"Highly Popular", IF(Table13[[#This Row],[Number_Review_Lakhs]]>=0.5,"Popular","Less Popular")) -> Less Popular | S235: =IF(Table13[[#This Row],[Visit_Time_Hrs]]<=2,"Short Visit", IF(Table13[[#This Row],[Visit_Time_Hrs]]<=5,"Medium Visit","Full Day")) -> Short Visit | T235: =IF(Table13[[#This Row],[Airport_50km_Radius]]="Yes","Accessible","Remote") -> Remote | U235: =IF(Table13[[#This Row],[Reiew_Rating]]>=4.7,"Yes","No") -> No | V235: =IF(OR(N235="Historical",N235="Artistic",N235="Religious",N235="Architectural"), "Heritage & Culture", IF(OR(N235="Environmental",N235="Botanical",N235="Scenic",N235="Wildlife",N235="Nature"), "Nature & Wildlife", IF(OR(N235="Recreational",N235="Market",N235="Entertainment"), "Leisure & Commerce", IF(N235="Scientific", "Science & Education", "Other")))) -> Nature & Wildlife | W235: =REPT("★", ROUND(H235, 0)) & REPT("☆", 5 - ROUND(H235, 0)) -> ★★★★☆ | X235: =ROUND(H235, 0) & " / 5 Stars" -> 4 / 5 Stars | Y235: =IF(P235>=1.5, "High Traffic", IF(P235>=0.4, "Medium Traffic", "Low Traffic")) -> Low Traffic
A236: Eastern | B236: Odisha | C236: Balasore | D236: Chandipur Beach | E236: Beach | F236: 1483 | G236: 1.5 | H236: 4.2 | I236: =IF(Table13[[#This Row],[Reiew_Rating]]>=4.5,"Excellent", IF(Table13[[#This Row],[Reiew_Rating]]>=4,"Good","Average")) -> Good | J236: 0 | K236: =IF(Table13[[#This Row],[Entrance_Fee_INR]]=0,"Free","Paid") -> Free | L236: Yes | M236: Sunday | N236: Recreational | O236: Yes | P236: 0.014 | Q236: Morning | R236: =IF(Table13[[#This Row],[Number_Review_Lakhs]]>=1,"Highly Popular", IF(Table13[[#This Row],[Number_Review_Lakhs]]>=0.5,"Popular","Less Popular")) -> Less Popular | S236: =IF(Table13[[#This Row],[Visit_Time_Hrs]]<=2,"Short Visit", IF(Table13[[#This Row],[Visit_Time_Hrs]]<=5,"Medium Visit","Full Day")) -> Short Visit | T236: =IF(Table13[[#This Row],[Airport_50km_Radius]]="Yes","Accessible","Remote") -> Accessible | U236: =IF(Table13[[#This Row],[Reiew_Rating]]>=4.7,"Yes","No") -> No | V236: =IF(OR(N236="Historical",N236="Artistic",N236="Religious",N236="Architectural"), "Heritage & Culture", IF(OR(N236="Environmental",N236="Botanical",N236="Scenic",N236="Wildlife",N236="Nature"), "Nature & Wildlife", IF(OR(N236="Recreational",N236="Market",N236="Entertainment"), "Leisure & Commerce", IF(N236="Scientific", "Science & Education", "Other")))) -> Leisure & Commerce | W236: =REPT("★", ROUND(H236, 0)) & REPT("☆", 5 - ROUND(H236, 0)) -> ★★★★☆ | X236: =ROUND(H236, 0) & " / 5 Stars" -> 4 / 5 Stars | Y236: =IF(P236>=1.5, "High Traffic", IF(P236>=0.4, "Medium Traffic", "Low Traffic")) -> Low Traffic
A237: Eastern | B237: Odisha | C237: Kendujhar | D237: Sanaghagara Waterfall | E237: Waterfall | F237: 1929 | G237: 1 | H237: 4.4 | I237: =IF(Table13[[#This Row],[Reiew_Rating]]>=4.5,"Excellent", IF(Table13[[#This Row],[Reiew_Rating]]>=4,"Good","Average")) -> Good | J237: 0 | K237: =IF(Table13[[#This Row],[Entrance_Fee_INR]]=0,"Free","Paid") -> Free | L237: No | M237: Wednesday | N237: Nature | O237: Yes | P237: 0.055 | Q237: All | R237: =IF(Table13[[#This Row],[Number_Review_Lakhs]]>=1,"Highly Popular", IF(Table13[[#This Row],[Number_Review_Lakhs]]>=0.5,"Popular","Less Popular")) -> Less Popular | S237: =IF(Table13[[#This Row],[Visit_Time_Hrs]]<=2,"Short Visit", IF(Table13[[#This Row],[Visit_Time_Hrs]]<=5,"Medium Visit","Full Day")) -> Short Visit | T237: =IF(Table13[[#This Row],[Airport_50km_Radius]]="Yes","Accessible","Remote") -> Remote | U237: =IF(Table13[[#This Row],[Reiew_Rating]]>=4.7,"Yes","No") -> No | V237: =IF(OR(N237="Historical",N237="Artistic",N237="Religious",N237="Architectural"), "Heritage & Culture", IF(OR(N237="Environmental",N237="Botanical",N237="Scenic",N237="Wildlife",N237="Nature"), "Nature & Wildlife", IF(OR(N237="Recreational",N237="Market",N237="Entertainment"), "Leisure & Commerce", IF(N237="Scientific", "Science & Education", "Other")))) -> Nature & Wildlife | W237: =REPT("★", ROUND(H237, 0)) & REPT("☆", 5 - ROUND(H237, 0)) -> ★★★★☆ | X237: =ROUND(H237, 0) & " / 5 Stars" -> 4 / 5 Stars | Y237: =IF(P237>=1.5, "High Traffic", IF(P237>=0.4, "Medium Traffic", "Low Traffic")) -> Low Traffic
A238: Southern | B238: Tamil Nadu | C238: Chennai | D238: Marina Beach | E238: Beach | F238: 1413 | G238: 1.5 | H238: 3.9 | I238: =IF(Table13[[#This Row],[Reiew_Rating]]>=4.5,"Excellent", IF(Table13[[#This Row],[Reiew_Rating]]>=4,"Good","Average")) -> Average | J238: 0 | K238: =IF(Table13[[#This Row],[Entrance_Fee_INR]]=0,"Free","Paid") -> Free | L238: Yes | M238: Thursday | N238: Recreational | O238: Yes | P238: 0.1 | Q238: Morning | R238: =IF(Table13[[#This Row],[Number_Review_Lakhs]]>=1,"Highly Popular", IF(Table13[[#This Row],[Number_Review_Lakhs]]>=0.5,"Popular","Less Popular")) -> Less Popular | S238: =IF(Table13[[#This Row],[Visit_Time_Hrs]]<=2,"Short Visit", IF(Table13[[#This Row],[Visit_Time_Hrs]]<=5,"Medium Visit","Full Day")) -> Short Visit | T238: =IF(Table13[[#This Row],[Airport_50km_Radius]]="Yes","Accessible","Remote") -> Accessible | U238: =IF(Table13[[#This Row],[Reiew_Rating]]>=4.7,"Yes","No") -> No | V238: =IF(OR(N238="Historical",N238="Artistic",N238="Religious",N238="Architectural"), "Heritage & Culture", IF(OR(N238="Environmental",N238="Botanical",N238="Scenic",N238="Wildlife",N238="Nature"), "Nature & Wildlife", IF(OR(N238="Recreational",N238="Market",N238="Entertainment"), "Leisure & Commerce", IF(N238="Scientific", "Science & Education", "Other")))) -> Leisure & Commerce | W238: =REPT("★", ROUND(H238, 0)) & REPT("☆", 5 - ROUND(H238, 0)) -> ★★★★☆ | X238: =ROUND(H238, 0) & " / 5 Stars" -> 4 / 5 Stars | Y238: =IF(P238>=1.5, "High Traffic", IF(P238>=0.4, "Medium Traffic", "Low Traffic")) -> Low Traffic
A239: Southern | B239: Tamil Nadu | C239: Madurai | D239: Meenakshi Amman Temple | E239: Temple | F239: 6th century AD | G239: 2 | H239: 4.7 | I239: =IF(Table13[[#This Row],[Reiew_Rating]]>=4.5,"Excellent", IF(Table13[[#This Row],[Reiew_Rating]]>=4,"Good","Average")) -> Excellent | J239: 0 | K239: =IF(Table13[[#This Row],[Entrance_Fee_INR]]=0,"Free","Paid") -> Free | L239: Yes | M239: Monday | N239: Religious | O239: No | P239: 0.65 | Q239: All | R239: =IF(Table13[[#This Row],[Number_Review_Lakhs]]>=1,"Highly Popular", IF(Table13[[#This Row],[Number_Review_Lakhs]]>=0.5,"Popular","Less Popular")) -> Popular | S239: =IF(Table13[[#This Row],[Visit_Time_Hrs]]<=2,"Short Visit", IF(Table13[[#This Row],[Visit_Time_Hrs]]<=5,"Medium Visit","Full Day")) -> Short Visit | T239: =IF(Table13[[#This Row],[Airport_50km_Radius]]="Yes","Accessible","Remote") -> Accessible | U239: =IF(Table13[[#This Row],[Reiew_Rating]]>=4.7,"Yes","No") -> Yes | V239: =IF(OR(N239="Historical",N239="Artistic",N239="Religious",N239="Architectural"), "Heritage & Culture", IF(OR(N239="Environmental",N239="Botanical",N239="Scenic",N239="Wildlife",N239="Nature"), "Nature & Wildlife", IF(OR(N239="Recreational",N239="Market",N239="Entertainment"), "Leisure & Commerce", IF(N239="Scientific", "Science & Education", "Other")))) -> Heritage & Culture | W239: =REPT("★", ROUND(H239, 0)) & REPT("☆", 5 - ROUND(H239, 0)) -> ★★★★★ | X239: =ROUND(H239, 0) & " / 5 Stars" -> 5 / 5 Stars | Y239: =IF(P239>=1.5, "High Traffic", IF(P239>=0.4, "Medium Traffic", "Low Traffic")) -> Medium Traffic
A240: Southern | B240: Tamil Nadu | C240: Rameswaram | D240: Ramanathaswamy Temple | E240: Temple | F240: 12th century | G240: 1.5 | H240: 4.6 | I240: =IF(Table13[[#This Row],[Reiew_Rating]]>=4.5,"Excellent", IF(Table13[[#This Row],[Reiew_Rating]]>=4,"Good","Average")) -> Excellent | J240: 0 | K240: =IF(Table13[[#This Row],[Entrance_Fee_INR]]=0,"Free","Paid") -> Free | L240: No | M240: Saturday | N240: Religious | O240: No | P240: 0.01 | Q240: All | R240: =IF(Table13[[#This Row],[Number_Review_Lakhs]]>=1,"Highly Popular", IF(Table13[[#This Row],[Number_Review_Lakhs]]>=0.5,"Popular","Less Popular")) -> Less Popular | S240: =IF(Table13[[#This Row],[Visit_Time_Hrs]]<=2,"Short Visit", IF(Table13[[#This Row],[Visit_Time_Hrs]]<=5,"Medium Visit","Full Day")) -> Short Visit | T240: =IF(Table13[[#This Row],[Airport_50km_Radius]]="Yes","Accessible","Remote") -> Remote | U240: =IF(Table13[[#This Row],[Reiew_Rating]]>=4.7,"Yes","No") -> No | V240: =IF(OR(N240="Historical",N240="Artistic",N240="Religious",N240="Architectural"), "Heritage & Culture", IF(OR(N240="Environmental",N240="Botanical",N240="Scenic",N240="Wildlife",N240="Nature"), "Nature & Wildlife", IF(OR(N240="Recreational",N240="Market",N240="Entertainment"), "Leisure & Commerce", IF(N240="Scientific", "Science & Education", "Other")))) -> Heritage & Culture | W240: =REPT("★", ROUND(H240, 0)) & REPT("☆", 5 - ROUND(H240, 0)) -> ★★★★★ | X240: =ROUND(H240, 0) & " / 5 Stars" -> 5 / 5 Stars | Y240: =IF(P240>=1.5, "High Traffic", IF(P240>=0.4, "Medium Traffic", "Low Traffic")) -> Low Traffic
A241: Southern | B241: Tamil Nadu | C241: Kanyakumari | D241: Vivekananda Rock Memorial | E241: Memorial | F241: 1970 | G241: 1 | H241: 4.6 | I241: =IF(Table13[[#This Row],[Reiew_Rating]]>=4.5,"Excellent", IF(Table13[[#This Row],[Reiew_Rating]]>=4,"Good","Average")) -> Excellent | J241: 20 | K241: =IF(Table13[[#This Row],[Entrance_Fee_INR]]=0,"Free","Paid") -> Paid | L241: Yes | M241: Wednesday | N241: Historical | O241: No | P241: 0.47 | Q241: Morning | R241: =IF(Table13[[#This Row],[Number_Review_Lakhs]]>=1,"Highly Popular", IF(Table13[[#This Row],[Number_Review_Lakhs]]>=0.5,"Popular","Less Popular")) -> Less Popular | S241: =IF(Table13[[#This Row],[Visit_Time_Hrs]]<=2,"Short Visit", IF(Table13[[#This Row],[Visit_Time_Hrs]]<=5,"Medium Visit","Full Day")) -> Short Visit | T241: =IF(Table13[[#This Row],[Airport_50km_Radius]]="Yes","Accessible","Remote") -> Accessible | U241: =IF(Table13[[#This Row],[Reiew_Rating]]>=4.7,"Yes","No") -> No | V241: =IF(OR(N241="Historical",N241="Artistic",N241="Religious",N241="Architectural"), "Heritage & Culture", IF(OR(N241="Environmental",N241="Botanical",N241="Scenic",N241="Wildlife",N241="Nature"), "Nature & Wildlife", IF(OR(N241="Recreational",N241="Market",N241="Entertainment"), "Leisure & Commerce", IF(N241="Scientific", "Science & Education", "Other")))) -> Heritage & Culture | W241: =REPT("★", ROUND(H241, 0)) & REPT("☆", 5 - ROUND(H241, 0)) -> ★★★★★ | X241: =ROUND(H241, 0) & " / 5 Stars" -> 5 / 5 Stars | Y241: =IF(P241>=1.5, "High Traffic", IF(P241>=0.4, "Medium Traffic", "Low Traffic")) -> Medium Traffic
A242: Southern | B242: Tamil Nadu | C242: Ooty | D242: Ooty Lake | E242: Lake | F242: 1824 | G242: 1 | H242: 4.1 | I242: =IF(Table13[[#This Row],[Reiew_Rating]]>=4.5,"Excellent", IF(Table13[[#This Row],[Reiew_Rating]]>=4,"Good","Average")) -> Good | J242: 10 | K242: =IF(Table13[[#This Row],[Entrance_Fee_INR]]=0,"Free","Paid") -> Paid | L242: Yes | M242: Tuesday | N242: Recreational | O242: Yes | P242: 0.61 | Q242: Morning | R242: =IF(Table13[[#This Row],[Number_Review_Lakhs]]>=1,"Highly Popular", IF(Table13[[#This Row],[Number_Review_Lakhs]]>=0.5,"Popular","Less Popular")) -> Popular | S242: =IF(Table13[[#This Row],[Visit_Time_Hrs]]<=2,"Short Visit", IF(Table13[[#This Row],[Visit_Time_Hrs]]<=5,"Medium Visit","Full Day")) -> Short Visit | T242: =IF(Table13[[#This Row],[Airport_50km_Radius]]="Yes","Accessible","Remote") -> Accessible | U242: =IF(Table13[[#This Row],[Reiew_Rating]]>=4.7,"Yes","No") -> No | V242: =IF(OR(N242="Historical",N242="Artistic",N242="Religious",N242="Architectural"), "Heritage & Culture", IF(OR(N242="Environmental",N242="Botanical",N242="Scenic",N242="Wildlife",N242="Nature"), "Nature & Wildlife", IF(OR(N242="Recreational",N242="Market",N242="Entertainment"), "Leisure & Commerce", IF(N242="Scientific", "Science & Education", "Other")))) -> Leisure & Commerce | W242: =REPT("★", ROUND(H242, 0)) & REPT("☆", 5 - ROUND(H242, 0)) -> ★★★★☆ | X242: =ROUND(H242, 0) & " / 5 Stars" -> 4 / 5 Stars | Y242: =IF(P242>=1.5, "High Traffic", IF(P242>=0.4, "Medium Traffic", "Low Traffic")) -> Medium Traffic
A243: Southern | B243: Tamil Nadu | C243: Coimbatore | D243: Marudamalai Temple | E243: Temple | F243: 12th century | G243: 1 | H243: 4.7 | I243: =IF(Table13[[#This Row],[Reiew_Rating]]>=4.5,"Excellent", IF(Table13[[#This Row],[Reiew_Rating]]>=4,"Good","Average")) -> Excellent | J243: 0 | K243: =IF(Table13[[#This Row],[Entrance_Fee_INR]]=0,"Free","Paid") -> Free | L243: Yes | M243: Thursday | N243: Religious | O243: No | P243: 0.3 | Q243: All | R243: =IF(Table13[[#This Row],[Number_Review_Lakhs]]>=1,"Highly Popular", IF(Table13[[#This Row],[Number_Review_Lakhs]]>=0.5,"Popular","Less Popular")) -> Less Popular | S243: =IF(Table13[[#This Row],[Visit_Time_Hrs]]<=2,"Short Visit", IF(Table13[[#This Row],[Visit_Time_Hrs]]<=5,"Medium Visit","Full Day")) -> Short Visit | T243: =IF(Table13[[#This Row],[Airport_50km_Radius]]="Yes","Accessible","Remote") -> Accessible | U243: =IF(Table13[[#This Row],[Reiew_Rating]]>=4.7,"Yes","No") -> Yes | V243: =IF(OR(N243="Historical",N243="Artistic",N243="Religious",N243="Architectural"), "Heritage & Culture", IF(OR(N243="Environmental",N243="Botanical",N243="Scenic",N243="Wildlife",N243="Nature"), "Nature & Wildlife", IF(OR(N243="Recreational",N243="Market",N243="Entertainment"), "Leisure & Commerce", IF(N243="Scientific", "Science & Education", "Other")))) -> Heritage & Culture | W243: =REPT("★", ROUND(H243, 0)) & REPT("☆", 5 - ROUND(H243, 0)) -> ★★★★★ | X243: =ROUND(H243, 0) & " / 5 Stars" -> 5 / 5 Stars | Y243: =IF(P243>=1.5, "High Traffic", IF(P243>=0.4, "Medium Traffic", "Low Traffic")) -> Low Traffic
A244: Southern | B244: Tamil Nadu | C244: Kodaikanal | D244: Kodaikanal Lake | E244: Lake | F244: 1863 | G244: 2 | H244: 3.9 | I244: =IF(Table13[[#This Row],[Reiew_Rating]]>=4.5,"Excellent", IF(Table13[[#This Row],[Reiew_Rating]]>=4,"Good","Average")) -> Average | J244: 0 | K244: =IF(Table13[[#This Row],[Entrance_Fee_INR]]=0,"Free","Paid") -> Free | L244: No | M244: Friday | N244: Recreational | O244: Yes | P244: 0.1 | Q244: Morning | R244: =IF(Table13[[#This Row],[Number_Review_Lakhs]]>=1,"Highly Popular", IF(Table13[[#This Row],[Number_Review_Lakhs]]>=0.5,"Popular","Less Popular")) -> Less Popular | S244: =IF(Table13[[#This Row],[Visit_Time_Hrs]]<=2,"Short Visit", IF(Table13[[#This Row],[Visit_Time_Hrs]]<=5,"Medium Visit","Full Day")) -> Short Visit | T244: =IF(Table13[[#This Row],[Airport_50km_Radius]]="Yes","Accessible","Remote") -> Remote | U244: =IF(Table13[[#This Row],[Reiew_Rating]]>=4.7,"Yes","No") -> No | V244: =IF(OR(N244="Historical",N244="Artistic",N244="Religious",N244="Architectural"), "Heritage & Culture", IF(OR(N244="Environmental",N244="Botanical",N244="Scenic",N244="Wildlife",N244="Nature"), "Nature & Wildlife", IF(OR(N244="Recreational",N244="Market",N244="Entertainment"), "Leisure & Commerce", IF(N244="Scientific", "Science & Education", "Other")))) -> Leisure & Commerce | W244: =REPT("★", ROUND(H244, 0)) & REPT("☆", 5 - ROUND(H244, 0)) -> ★★★★☆ | X244: =ROUND(H244, 0) & " / 5 Stars" -> 4 / 5 Stars | Y244: =IF(P244>=1.5, "High Traffic", IF(P244>=0.4, "Medium Traffic", "Low Traffic")) -> Low Traffic
A245: Southern | B245: Tamil Nadu | C245: Thanjavur | D245: Brihadeeswarar Temple | E245: Temple | F245: 110 | G245: 1.5 | H245: 4.8 | I245: =IF(Table13[[#This Row],[Reiew_Rating]]>=4.5,"Excellent", IF(Table13[[#This Row],[Reiew_Rating]]>=4,"Good","Average")) -> Excellent | J245: 0 | K245: =IF(Table13[[#This Row],[Entrance_Fee_INR]]=0,"Free","Paid") -> Free | L245: Yes | M245: Friday | N245: Religious | O245: No | P245: 0.35 | Q245: All | R245: =IF(Table13[[#This Row],[Number_Review_Lakhs]]>=1,"Highly Popular", IF(Table13[[#This Row],[Number_Review_Lakhs]]>=0.5,"Popular","Less Popular")) -> Less Popular | S245: =IF(Table13[[#This Row],[Visit_Time_Hrs]]<=2,"Short Visit", IF(Table13[[#This Row],[Visit_Time_Hrs]]<=5,"Medium Visit","Full Day")) -> Short Visit | T245: =IF(Table13[[#This Row],[Airport_50km_Radius]]="Yes","Accessible","Remote") -> Accessible | U245: =IF(Table13[[#This Row],[Reiew_Rating]]>=4.7,"Yes","No") -> Yes | V245: =IF(OR(N245="Historical",N245="Artistic",N245="Religious",N245="Architectural"), "Heritage & Culture", IF(OR(N245="Environmental",N245="Botanical",N245="Scenic",N245="Wildlife",N245="Nature"), "Nature & Wildlife", IF(OR(N245="Recreational",N245="Market",N245="Entertainment"), "Leisure & Commerce", IF(N245="Scientific", "Science & Education", "Other")))) -> Heritage & Culture | W245: =REPT("★", ROUND(H245, 0)) & REPT("☆", 5 - ROUND(H245, 0)) -> ★★★★★ | X245: =ROUND(H245, 0) & " / 5 Stars" -> 5 / 5 Stars | Y245: =IF(P245>=1.5, "High Traffic", IF(P245>=0.4, "Medium Traffic", "Low Traffic")) -> Low Traffic
A246: Southern | B246: Tamil Nadu | C246: Mahabalipuram | D246: Shore Temple | E246: Temple | F246: 7th century | G246: 1 | H246: 4.6 | I246: =IF(Table13[[#This Row],[Reiew_Rating]]>=4.5,"Excellent", IF(Table13[[#This Row],[Reiew_Rating]]>=4,"Good","Average")) -> Excellent | J246: 40 | K246: =IF(Table13[[#This Row],[Entrance_Fee_INR]]=0,"Free","Paid") -> Paid | L246: Yes | M246: Tuesday | N246: Historical | O246: No | P246: 0.09 | Q246: All | R246: =IF(Table13[[#This Row],[Number_Review_Lakhs]]>=1,"Highly Popular", IF(Table13[[#This Row],[Number_Review_Lakhs]]>=0.5,"Popular","Less Popular")) -> Less Popular | S246: =IF(Table13[[#This Row],[Visit_Time_Hrs]]<=2,"Short Visit", IF(Table13[[#This Row],[Visit_Time_Hrs]]<=5,"Medium Visit","Full Day")) -> Short Visit | T246: =IF(Table13[[#This Row],[Airport_50km_Radius]]="Yes","Accessible","Remote") -> Accessible | U246: =IF(Table13[[#This Row],[Reiew_Rating]]>=4.7,"Yes","No") -> No | V246: =IF(OR(N246="Historical",N246="Artistic",N246="Religious",N246="Architectural"), "Heritage & Culture", IF(OR(N246="Environmental",N246="Botanical",N246="Scenic",N246="Wildlife",N246="Nature"), "Nature & Wildlife", IF(OR(N246="Recreational",N246="Market",N246="Entertainment"), "Leisure & Commerce", IF(N246="Scientific", "Science & Education", "Other")))) -> Heritage & Culture | W246: =REPT("★", ROUND(H246, 0)) & REPT("☆", 5 - ROUND(H246, 0)) -> ★★★★★ | X246: =ROUND(H246, 0) & " / 5 Stars" -> 5 / 5 Stars | Y246: =IF(P246>=1.5, "High Traffic", IF(P246>=0.4, "Medium Traffic", "Low Traffic")) -> Low Traffic
